Workbook

Sheet Cover
A1: Statistical Analysis Sample Workbook
F5: Sample study: mentoring, study habits, and academic performance
F8: Prepared as an Excel-based sample deliverable for RE4U Research Edit4u Solutions
F12: Research objective | G12: Determine whether a structured mentoring program improves final exam performance and identify the behavioural factors linked to scores.
F14: Dataset | G14: 120 anonymized student records with variables that directly match the objective: group, study hours, attendance, sleep, pre-test, post-test, and final exam score.
F16: Tests included | G16: Descriptive statistics, independent t-test, paired t-test, Pearson correlation, simple linear regression, and one-way ANOVA.
F18: Outputs | G18: Raw data, dictionary, data quality screen, formula-driven analysis tables, dashboard charts, and detailed interpretation notes.
A24: Workbook flow: Cover → Read Me → Data Dictionary → Raw Data → Data Quality → Descriptive Stats → Test Results → Interpretation Notes → Dashboard
A26: Use this sample as a template and replace the objective, variables, and narrative with the client’s actual study scope.

Sheet Read Me
A1: Research design and why each test is used
A4: Primary objective: determine whether students in the mentoring program perform better than the control group, and quantify whether study hours and attendance are associated with better final exam outcomes.
A8: Research objective | B8: Test used | C8: Purpose of the test | D8: Variables involved | E8: Why this test fits | F8: Decision rule / what to read
A9: Summarize the sample before testing hypotheses. | B9: Descriptive statistics | C9: Provides means, standard deviations, ranges, and sample counts. | D9: Age, study hours, attendance, sleep, pre-test, post-test, final score, group, gender. | E9: This is the first step in any analysis because it shows whether the data look reasonable and comparable. | F9: Review mean, SD, min, max, and group counts.
A10: Compare final exam scores between mentored and control students. | B10: Independent samples t-test (Welch) | C10: Tests whether two unrelated groups have different mean scores. | D10: Program_Group and Final_Exam_Score. | E10: The groups are made up of different students, so an independent test is required. | F10: If p < 0.05, conclude the group means differ significantly.
A11: Check whether mentored students improved over time. | B11: Paired samples t-test | C11: Tests whether the average within-student change is different from zero. | D11: Pre_Test_Score and Post_Test_Score for mentored students only. | E11: The same students are observed twice, so the paired design is appropriate. | F11: If p < 0.05, conclude the average improvement is statistically significant.
A12: Measure the linear relationship between study hours and final score. | B12: Pearson correlation + regression | C12: Correlation measures strength/direction; regression estimates the score change per extra study hour. | D12: Study_Hours_per_Week and Final_Exam_Score. | E12: Both variables are numeric and the question is about association and prediction. | F12: Read r, slope, intercept, R², and p-value.
A13: Compare scores across low, medium, and high attendance categories. | B13: One-way ANOVA | C13: Tests whether three or more independent groups have the same mean score. | D13: Attendance_Category and Final_Exam_Score. | E13: Attendance is grouped into three levels, so ANOVA avoids multiple pairwise t-tests. | F13: If p < 0.05, at least one attendance-group mean differs from the others.
A15: Significance level used in this sample: alpha = 0.05. Interpretation should combine p-values with effect size and real-world meaning.

Sheet Data Dictionary
A1: Data dictionary
A4: Variable | B4: Meaning | C4: Type | D4: Scale | E4: Role in analysis | F4: Expected range / levels | G4: Why it is included
A5: Student_ID | B5: Unique row identifier | C5: Text | D5: Nominal | E5: Record key | F5: S001 to S120 | G5: Keeps each observation unique.
A6: Program_Group | B6: Mentoring status | C6: Text | D6: Nominal | E6: Main grouping variable | F6: Mentored / Control | G6: Used to test program impact.
A7: Gender | B7: Student gender | C7: Text | D7: Nominal | E7: Descriptive subgroup | F7: Female / Male | G7: Profiles sample composition.
A8: Age_Years | B8: Age in years | C8: Numeric | D8: Scale | E8: Descriptive covariate | F8: 18 to 26 | G8: Checks that the sample matches the target student age range.
A9: Study_Hours_per_Week | B9: Average weekly study hours | C9: Numeric | D9: Scale | E9: Predictor | F9: 2.0 to 14.5 hours | G9: Tests whether greater study time is associated with higher scores.
A10: Attendance_Pct | B10: Semester attendance percentage | C10: Numeric | D10: Scale | E10: Predictor / grouping source | F10: 60.0 to 99.0% | G10: Measures consistency of class participation.
A11: Sleep_Hours_per_Night | B11: Average sleep hours per night | C11: Numeric | D11: Scale | E11: Descriptive covariate | F11: 5.0 to 9.0 hours | G11: Adds context on student routine and wellbeing.
A12: Pre_Test_Score | B12: Baseline score before intervention | C12: Numeric | D12: Scale | E12: Paired baseline outcome | F12: 40.0 to 82.0 | G12: Needed for before-vs-after improvement analysis.
A13: Post_Test_Score | B13: Follow-up score after program period | C13: Numeric | D13: Scale | E13: Paired follow-up outcome | F13: 45.0 to 98.0 | G13: Paired with pre-test to assess improvement.
A14: Final_Exam_Score | B14: End-semester exam score | C14: Numeric | D14: Scale | E14: Primary outcome | F14: 45.0 to 99.0 | G14: Main performance outcome for impact and prediction analysis.
A15: Attendance_Category | B15: Attendance band derived from Attendance_Pct | C15: Text | D15: Ordinal | E15: ANOVA group | F15: Low <75, Medium 75-89.9, High ≥90 | G15: Required to compare three attendance groups.

Sheet Raw Data
A1: Student_ID | B1: Program_Group | C1: Gender | D1: Age_Years | E1: Study_Hours_per_Week | F1: Attendance_Pct | G1: Sleep_Hours_per_Night | H1: Pre_Test_Score | I1: Post_Test_Score | J1: Final_Exam_Score | K1: Attendance_Category
A2: S001 | B2: Mentored | C2: Male | D2: 20 | E2: 8.1 | F2: 84.2 | G2: 5.7 | H2: 61.2 | I2: 75 | J2: 68.2 | K2: =IF(F2<75,"Low",IF(F2<90,"Medium","High")) -> Medium
A3: S002 | B3: Mentored | C3: Male | D3: 22 | E3: 6.1 | F3: 85.7 | G3: 7.4 | H3: 59.6 | I3: 68.2 | J3: 78.6 | K3: =IF(F3<75,"Low",IF(F3<90,"Medium","High")) -> Medium
A4: S003 | B4: Mentored | C4: Female | D4: 21 | E4: 9 | F4: 85.1 | G4: 6.6 | H4: 54 | I4: 69.6 | J4: 78.6 | K4: =IF(F4<75,"Low",IF(F4<90,"Medium","High")) -> Medium
A5: S004 | B5: Control | C5: Male | D5: 21 | E5: 8.6 | F5: 91.2 | G5: 5 | H5: 57.7 | I5: 67.1 | J5: 80.3 | K5: =IF(F5<75,"Low",IF(F5<90,"Medium","High")) -> High
A6: S005 | B6: Mentored | C6: Female | D6: 21 | E6: 8.7 | F6: 90.9 | G6: 7.6 | H6: 57.6 | I6: 70.3 | J6: 89.2 | K6: =IF(F6<75,"Low",IF(F6<90,"Medium","High")) -> High
A7: S006 | B7: Control | C7: Female | D7: 22 | E7: 7.8 | F7: 76.2 | G7: 7.2 | H7: 50.9 | I7: 64.3 | J7: 70.6 | K7: =IF(F7<75,"Low",IF(F7<90,"Medium","High")) -> Medium
A8: S007 | B8: Control | C8: Female | D8: 23 | E8: 8 | F8: 91.2 | G8: 6.4 | H8: 64.2 | I8: 79.4 | J8: 77 | K8: =IF(F8<75,"Low",IF(F8<90,"Medium","High")) -> High
A9: S008 | B9: Mentored | C9: Male | D9: 21 | E9: 11.7 | F9: 97.2 | G9: 5.9 | H9: 67.1 | I9: 82.6 | J9: 94.5 | K9: =IF(F9<75,"Low",IF(F9<90,"Medium","High")) -> High
A10: S009 | B10: Mentored | C10: Female | D10: 22 | E10: 7.7 | F10: 86.3 | G10: 7.7 | H10: 48.6 | I10: 66.9 | J10: 72.8 | K10: =IF(F10<75,"Low",IF(F10<90,"Medium","High")) -> Medium
A11: S010 | B11: Mentored | C11: Female | D11: 18 | E11: 7.8 | F11: 98.5 | G11: 7.3 | H11: 61.5 | I11: 81.4 | J11: 85.1 | K11: =IF(F11<75,"Low",IF(F11<90,"Medium","High")) -> High
A12: S011 | B12: Control | C12: Female | D12: 21 | E12: 5.3 | F12: 68.6 | G12: 8.9 | H12: 68.9 | I12: 84.1 | J12: 81.3 | K12: =IF(F12<75,"Low",IF(F12<90,"Medium","High")) -> Low
A13: S012 | B13: Control | C13: Female | D13: 20 | E13: 4.8 | F13: 68.9 | G13: 7.3 | H13: 67.1 | I13: 78.6 | J13: 69.2 | K13: =IF(F13<75,"Low",IF(F13<90,"Medium","High")) -> Low
... A121: S120 | B121: Mentored | C121: Female | D121: 23 | E121: 5.4 | F121: 96.9 | G121: 7.2 | H121: 76.9 | I121: 89.3 | J121: 92.8 | K121: =IF(F121<75,"Low",IF(F121<90,"Medium","High")) -> High

Sheet Data Quality
A1: Data quality and assumption screen
A4: Basic checks to complete before analysis: missing values, impossible ranges, and obvious data-entry issues.
A7: Variable | B7: Missing values | C7: Below allowed min | D7: Above allowed max | E7: Allowed rule | F7: Interpretation
A8: Student_ID | B8: =COUNTBLANK('Raw Data'!A2:A121) -> 0 | E8: No blanks | F8: Every record must have an ID.
A9: Program_Group | B9: =COUNTBLANK('Raw Data'!B2:B121) -> 0 | E9: Mentored / Control | F9: Each row needs a group assignment.
A10: Age_Years | B10: =COUNTBLANK('Raw Data'!D2:D121) -> 0 | C10: =COUNTIF('Raw Data'!D2:D121,"<18") -> 0 | D10: =COUNTIF('Raw Data'!D2:D121,">30") -> 0 | E10: 18 to 30 | F10: Out-of-range ages should be reviewed.
A11: Study_Hours_per_Week | B11: =COUNTBLANK('Raw Data'!E2:E121) -> 0 | C11: =COUNTIF('Raw Data'!E2:E121,"<0") -> 0 | D11: =COUNTIF('Raw Data'!E2:E121,">20") -> 0 | E11: 0 to 20 | F11: Negative or extreme study hours suggest entry problems.
A12: Attendance_Pct | B12: =COUNTBLANK('Raw Data'!F2:F121) -> 0 | C12: =COUNTIF('Raw Data'!F2:F121,"<0") -> 0 | D12: =COUNTIF('Raw Data'!F2:F121,">100") -> 0 | E12: 0 to 100% | F12: Percentages must remain bounded.
A13: Sleep_Hours_per_Night | B13: =COUNTBLANK('Raw Data'!G2:G121) -> 0 | C13: =COUNTIF('Raw Data'!G2:G121,"<0") -> 0 | D13: =COUNTIF('Raw Data'!G2:G121,">24") -> 0 | E13: 0 to 24 | F13: Implausible daily values should be checked.
A14: Pre_Test_Score | B14: =COUNTBLANK('Raw Data'!H2:H121) -> 0 | C14: =COUNTIF('Raw Data'!H2:H121,"<0") -> 0 | D14: =COUNTIF('Raw Data'!H2:H121,">100") -> 0 | E14: 0 to 100 | F14: Scores must remain within logical bounds.
A15: Post_Test_Score | B15: =COUNTBLANK('Raw Data'!I2:I121) -> 0 | C15: =COUNTIF('Raw Data'!I2:I121,"<0") -> 0 | D15: =COUNTIF('Raw Data'!I2:I121,">100") -> 0 | E15: 0 to 100 | F15: Scores must remain within logical bounds.
A16: Final_Exam_Score | B16: =COUNTBLANK('Raw Data'!J2:J121) -> 0 | C16: =COUNTIF('Raw Data'!J2:J121,"<0") -> 0 | D16: =COUNTIF('Raw Data'!J2:J121,">100") -> 0 | E16: 0 to 100 | F16: Scores must remain within logical bounds.
A19: Read this first | B19: If the missing-value and range-violation counts are zero, the dataset is ready for formal testing. If not, review and correct the affected rows before interpretation.

Sheet Descriptive Stats
A1: Descriptive statistics
A4: Variable | B4: Mean | C4: SD | D4: Min | E4: Max | F4: N | H4: Metric | I4: Mentored | J4: Control | K4: Difference (M-C) | L4: Interpretation
A5: Age_Years | B5: =AVERAGE('Raw Data'!D2:D121) -> 21.241667 | C5: =_xludf.STDEV.S('Raw Data'!D2:D121) -> #NAME? | D5: =MIN('Raw Data'!D2:D121) -> 18 | E5: =MAX('Raw Data'!D2:D121) -> 26 | F5: =COUNT('Raw Data'!D2:D121) -> 120 | H5: Sample size | I5: =COUNTIF('Raw Data'!B2:B121,"Mentored") -> 60 | J5: =COUNTIF('Raw Data'!B2:B121,"Control") -> 60 | K5: =I5-J5 -> 0 | L5: Should be similar if groups were balanced.
A6: Study_Hours_per_Week | B6: =AVERAGE('Raw Data'!E2:E121) -> 7.2816667 | C6: =_xludf.STDEV.S('Raw Data'!E2:E121) -> #NAME? | D6: =MIN('Raw Data'!E2:E121) -> 3.4 | E6: =MAX('Raw Data'!E2:E121) -> 12.5 | F6: =COUNT('Raw Data'!E2:E121) -> 120 | H6: Mean final score | I6: =AVERAGEIF('Raw Data'!B2:B121,"Mentored",'Raw Data'!J2:J121) -> 79.981667 | J6: =AVERAGEIF('Raw Data'!B2:B121,"Control",'Raw Data'!J2:J121) -> 75.243333 | K6: =I6-J6 -> 4.7383333 | L6: Positive value means the mentored group scored higher on average.
A7: Attendance_Pct | B7: =AVERAGE('Raw Data'!F2:F121) -> 83.6625 | C7: =_xludf.STDEV.S('Raw Data'!F2:F121) -> #NAME? | D7: =MIN('Raw Data'!F2:F121) -> 60.1 | E7: =MAX('Raw Data'!F2:F121) -> 98.9 | F7: =COUNT('Raw Data'!F2:F121) -> 120 | H7: Mean pre-test score | I7: =AVERAGEIF('Raw Data'!B2:B121,"Mentored",'Raw Data'!H2:H121) -> 59.648333 | J7: =AVERAGEIF('Raw Data'!B2:B121,"Control",'Raw Data'!H2:H121) -> 60.32 | K7: =I7-J7 -> -0.67166667 | L7: Shows whether groups were similar at baseline.
A8: Sleep_Hours_per_Night | B8: =AVERAGE('Raw Data'!G2:G121) -> 6.9958333 | C8: =_xludf.STDEV.S('Raw Data'!G2:G121) -> #NAME? | D8: =MIN('Raw Data'!G2:G121) -> 5 | E8: =MAX('Raw Data'!G2:G121) -> 8.9 | F8: =COUNT('Raw Data'!G2:G121) -> 120 | H8: Mean post-test score | I8: =AVERAGEIF('Raw Data'!B2:B121,"Mentored",'Raw Data'!I2:I121) -> 73.881667 | J8: =AVERAGEIF('Raw Data'!B2:B121,"Control",'Raw Data'!I2:I121) -> 72.545 | K8: =I8-J8 -> 1.3366667 | L8: Helps visualize post-program differences.
A9: Pre_Test_Score | B9: =AVERAGE('Raw Data'!H2:H121) -> 59.984167 | C9: =_xludf.STDEV.S('Raw Data'!H2:H121) -> #NAME? | D9: =MIN('Raw Data'!H2:H121) -> 40 | E9: =MAX('Raw Data'!H2:H121) -> 82 | F9: =COUNT('Raw Data'!H2:H121) -> 120 | H9: Mean study hours / week | I9: =AVERAGEIF('Raw Data'!B2:B121,"Mentored",'Raw Data'!E2:E121) -> 7.7333333 | J9: =AVERAGEIF('Raw Data'!B2:B121,"Control",'Raw Data'!E2:E121) -> 6.83 | K9: =I9-J9 -> 0.90333333 | L9: Provides behavioural context for score differences.
A10: Post_Test_Score | B10: =AVERAGE('Raw Data'!I2:I121) -> 73.213333 | C10: =_xludf.STDEV.S('Raw Data'!I2:I121) -> #NAME? | D10: =MIN('Raw Data'!I2:I121) -> 45 | E10: =MAX('Raw Data'!I2:I121) -> 98 | F10: =COUNT('Raw Data'!I2:I121) -> 120 | H10: Mean attendance % | I10: =AVERAGEIF('Raw Data'!B2:B121,"Mentored",'Raw Data'!F2:F121) -> 85.808333 | J10: =AVERAGEIF('Raw Data'!B2:B121,"Control",'Raw Data'!F2:F121) -> 81.516667 | K10: =I10-J10 -> 4.2916667 | L10: Higher attendance may partially explain better outcomes.
A11: Final_Exam_Score | B11: =AVERAGE('Raw Data'!J2:J121) -> 77.6125 | C11: =_xludf.STDEV.S('Raw Data'!J2:J121) -> #NAME? | D11: =MIN('Raw Data'!J2:J121) -> 51.8 | E11: =MAX('Raw Data'!J2:J121) -> 99 | F11: =COUNT('Raw Data'!J2:J121) -> 120
H13: Gender frequency | K13: Attendance category frequency
H14: Female | I14: =COUNTIF('Raw Data'!C2:C121,"Female") -> 67 | K14: Low | L14: =COUNTIF('Raw Data'!K2:K121,"Low") -> 18
H15: Male | I15: =COUNTIF('Raw Data'!C2:C121,"Male") -> 53 | K15: Medium | L15: =COUNTIF('Raw Data'!K2:K121,"Medium") -> 64
K16: High | L16: =COUNTIF('Raw Data'!K2:K121,"High") -> 38

Sheet Test Results
A1: Hypothesis test results (formula driven)
M2: =IF('Raw Data'!$B2="Mentored",'Raw Data'!$J2,"") -> 68.2 | N2: =IF('Raw Data'!$B2="Control",'Raw Data'!$J2,"") | P2: =IF('Raw Data'!$B2="Mentored",'Raw Data'!$H2,"") -> 61.2 | Q2: =IF('Raw Data'!$B2="Mentored",'Raw Data'!$I2,"") -> 75 | R2: =IF(AND(P2<>"",Q2<>""),Q2-P2,"") -> 13.8 | T2: =IF('Raw Data'!$K2="Low",'Raw Data'!$J2,"") | U2: =IF('Raw Data'!$K2="Medium",'Raw Data'!$J2,"") -> 68.2 | V2: =IF('Raw Data'!$K2="High",'Raw Data'!$J2,"")
M3: =IF('Raw Data'!$B3="Mentored",'Raw Data'!$J3,"") -> 78.6 | N3: =IF('Raw Data'!$B3="Control",'Raw Data'!$J3,"") | P3: =IF('Raw Data'!$B3="Mentored",'Raw Data'!$H3,"") -> 59.6 | Q3: =IF('Raw Data'!$B3="Mentored",'Raw Data'!$I3,"") -> 68.2 | R3: =IF(AND(P3<>"",Q3<>""),Q3-P3,"") -> 8.6 | T3: =IF('Raw Data'!$K3="Low",'Raw Data'!$J3,"") | U3: =IF('Raw Data'!$K3="Medium",'Raw Data'!$J3,"") -> 78.6 | V3: =IF('Raw Data'!$K3="High",'Raw Data'!$J3,"")
A4: A. Independent samples t-test: final exam score by program group | M4: =IF('Raw Data'!$B4="Mentored",'Raw Data'!$J4,"") -> 78.6 | N4: =IF('Raw Data'!$B4="Control",'Raw Data'!$J4,"") | P4: =IF('Raw Data'!$B4="Mentored",'Raw Data'!$H4,"") -> 54 | Q4: =IF('Raw Data'!$B4="Mentored",'Raw Data'!$I4,"") -> 69.6 | R4: =IF(AND(P4<>"",Q4<>""),Q4-P4,"") -> 15.6 | T4: =IF('Raw Data'!$K4="Low",'Raw Data'!$J4,"") | U4: =IF('Raw Data'!$K4="Medium",'Raw Data'!$J4,"") -> 78.6 | V4: =IF('Raw Data'!$K4="High",'Raw Data'!$J4,"")
A5: Purpose: compare the mean final exam score for two unrelated groups (Mentored vs Control). H0: both group means are equal. | M5: =IF('Raw Data'!$B5="Mentored",'Raw Data'!$J5,"") | N5: =IF('Raw Data'!$B5="Control",'Raw Data'!$J5,"") -> 80.3 | P5: =IF('Raw Data'!$B5="Mentored",'Raw Data'!$H5,"") | Q5: =IF('Raw Data'!$B5="Mentored",'Raw Data'!$I5,"") | R5: =IF(AND(P5<>"",Q5<>""),Q5-P5,"") | T5: =IF('Raw Data'!$K5="Low",'Raw Data'!$J5,"") | U5: =IF('Raw Data'!$K5="Medium",'Raw Data'!$J5,"") | V5: =IF('Raw Data'!$K5="High",'Raw Data'!$J5,"") -> 80.3
M6: =IF('Raw Data'!$B6="Mentored",'Raw Data'!$J6,"") -> 89.2 | N6: =IF('Raw Data'!$B6="Control",'Raw Data'!$J6,"") | P6: =IF('Raw Data'!$B6="Mentored",'Raw Data'!$H6,"") -> 57.6 | Q6: =IF('Raw Data'!$B6="Mentored",'Raw Data'!$I6,"") -> 70.3 | R6: =IF(AND(P6<>"",Q6<>""),Q6-P6,"") -> 12.7 | T6: =IF('Raw Data'!$K6="Low",'Raw Data'!$J6,"") | U6: =IF('Raw Data'!$K6="Medium",'Raw Data'!$J6,"") | V6: =IF('Raw Data'!$K6="High",'Raw Data'!$J6,"") -> 89.2
M7: =IF('Raw Data'!$B7="Mentored",'Raw Data'!$J7,"") | N7: =IF('Raw Data'!$B7="Control",'Raw Data'!$J7,"") -> 70.6 | P7: =IF('Raw Data'!$B7="Mentored",'Raw Data'!$H7,"") | Q7: =IF('Raw Data'!$B7="Mentored",'Raw Data'!$I7,"") | R7: =IF(AND(P7<>"",Q7<>""),Q7-P7,"") | T7: =IF('Raw Data'!$K7="Low",'Raw Data'!$J7,"") | U7: =IF('Raw Data'!$K7="Medium",'Raw Data'!$J7,"") -> 70.6 | V7: =IF('Raw Data'!$K7="High",'Raw Data'!$J7,"")
A8: Metric | B8: Mentored | C8: Control | D8: Result | M8: =IF('Raw Data'!$B8="Mentored",'Raw Data'!$J8,"") | N8: =IF('Raw Data'!$B8="Control",'Raw Data'!$J8,"") -> 77 | P8: =IF('Raw Data'!$B8="Mentored",'Raw Data'!$H8,"") | Q8: =IF('Raw Data'!$B8="Mentored",'Raw Data'!$I8,"") | R8: =IF(AND(P8<>"",Q8<>""),Q8-P8,"") | T8: =IF('Raw Data'!$K8="Low",'Raw Data'!$J8,"") | U8: =IF('Raw Data'!$K8="Medium",'Raw Data'!$J8,"") | V8: =IF('Raw Data'!$K8="High",'Raw Data'!$J8,"") -> 77
A9: n | B9: =COUNT(M2:M121) -> 60 | C9: =COUNT(N2:N121) -> 60 | M9: =IF('Raw Data'!$B9="Mentored",'Raw Data'!$J9,"") -> 94.5 | N9: =IF('Raw Data'!$B9="Control",'Raw Data'!$J9,"") | P9: =IF('Raw Data'!$B9="Mentored",'Raw Data'!$H9,"") -> 67.1 | Q9: =IF('Raw Data'!$B9="Mentored",'Raw Data'!$I9,"") -> 82.6 | R9: =IF(AND(P9<>"",Q9<>""),Q9-P9,"") -> 15.5 | T9: =IF('Raw Data'!$K9="Low",'Raw Data'!$J9,"") | U9: =IF('Raw Data'!$K9="Medium",'Raw Data'!$J9,"") | V9: =IF('Raw Data'!$K9="High",'Raw Data'!$J9,"") -> 94.5
A10: Mean final score | B10: =AVERAGE(M2:M121) -> 79.981667 | C10: =AVERAGE(N2:N121) -> 75.243333 | M10: =IF('Raw Data'!$B10="Mentored",'Raw Data'!$J10,"") -> 72.8 | N10: =IF('Raw Data'!$B10="Control",'Raw Data'!$J10,"") | P10: =IF('Raw Data'!$B10="Mentored",'Raw Data'!$H10,"") -> 48.6 | Q10: =IF('Raw Data'!$B10="Mentored",'Raw Data'!$I10,"") -> 66.9 | R10: =IF(AND(P10<>"",Q10<>""),Q10-P10,"") -> 18.3 | T10: =IF('Raw Data'!$K10="Low",'Raw Data'!$J10,"") | U10: =IF('Raw Data'!$K10="Medium",'Raw Data'!$J10,"") -> 72.8 | V10: =IF('Raw Data'!$K10="High",'Raw Data'!$J10,"")
A11: SD | B11: =_xludf.STDEV.S(M2:M121) -> #NAME? | C11: =_xludf.STDEV.S(N2:N121) -> #NAME? | M11: =IF('Raw Data'!$B11="Mentored",'Raw Data'!$J11,"") -> 85.1 | N11: =IF('Raw Data'!$B11="Control",'Raw Data'!$J11,"") | P11: =IF('Raw Data'!$B11="Mentored",'Raw Data'!$H11,"") -> 61.5 | Q11: =IF('Raw Data'!$B11="Mentored",'Raw Data'!$I11,"") -> 81.4 | R11: =IF(AND(P11<>"",Q11<>""),Q11-P11,"") -> 19.9 | T11: =IF('Raw Data'!$K11="Low",'Raw Data'!$J11,"") | U11: =IF('Raw Data'!$K11="Medium",'Raw Data'!$J11,"") | V11: =IF('Raw Data'!$K11="High",'Raw Data'!$J11,"") -> 85.1
A12: Welch t-statistic | D12: =(B10-C10)/SQRT((B11^2/B9)+(C11^2/C9)) -> #NAME? | M12: =IF('Raw Data'!$B12="Mentored",'Raw Data'!$J12,"") | N12: =IF('Raw Data'!$B12="Control",'Raw Data'!$J12,"") -> 81.3 | P12: =IF('Raw Data'!$B12="Mentored",'Raw Data'!$H12,"") | Q12: =IF('Raw Data'!$B12="Mentored",'Raw Data'!$I12,"") | R12: =IF(AND(P12<>"",Q12<>""),Q12-P12,"") | T12: =IF('Raw Data'!$K12="Low",'Raw Data'!$J12,"") -> 81.3 | U12: =IF('Raw Data'!$K12="Medium",'Raw Data'!$J12,"") | V12: =IF('Raw Data'!$K12="High",'Raw Data'!$J12,"")
A13: Degrees of freedom | D13: =((B11^2/B9 + C11^2/C9)^2)/(((B11^2/B9)^2/(B9-1))+((C11^2/C9)^2/(C9-1))) -> #NAME? | M13: =IF('Raw Data'!$B13="Mentored",'Raw Data'!$J13,"") | N13: =IF('Raw Data'!$B13="Control",'Raw Data'!$J13,"") -> 69.2 | P13: =IF('Raw Data'!$B13="Mentored",'Raw Data'!$H13,"") | Q13: =IF('Raw Data'!$B13="Mentored",'Raw Data'!$I13,"") | R13: =IF(AND(P13<>"",Q13<>""),Q13-P13,"") | T13: =IF('Raw Data'!$K13="Low",'Raw Data'!$J13,"") -> 69.2 | U13: =IF('Raw Data'!$K13="Medium",'Raw Data'!$J13,"") | V13: =IF('Raw Data'!$K13="High",'Raw Data'!$J13,"")
A14: p-value (two-tailed) | D14: =TDIST(ABS(D12),ROUND(D13,0),2) -> #NAME? | M14: =IF('Raw Data'!$B14="Mentored",'Raw Data'!$J14,"") | N14: =IF('Raw Data'!$B14="Control",'Raw Data'!$J14,"") -> 75.1 | P14: =IF('Raw Data'!$B14="Mentored",'Raw Data'!$H14,"") | Q14: =IF('Raw Data'!$B14="Mentored",'Raw Data'!$I14,"") | R14: =IF(AND(P14<>"",Q14<>""),Q14-P14,"") | T14: =IF('Raw Data'!$K14="Low",'Raw Data'!$J14,"") -> 75.1 | U14: =IF('Raw Data'!$K14="Medium",'Raw Data'!$J14,"") | V14: =IF('Raw Data'!$K14="High",'Raw Data'!$J14,"")
A15: Cohen's d | D15: =(B10-C10)/SQRT((((B9-1)*B11^2)+((C9-1)*C11^2))/(B9+C9-2)) -> #NAME? | M15: =IF('Raw Data'!$B15="Mentored",'Raw Data'!$J15,"") -> 81.2 | N15: =IF('Raw Data'!$B15="Control",'Raw Data'!$J15,"") | P15: =IF('Raw Data'!$B15="Mentored",'Raw Data'!$H15,"") -> 61.1 | Q15: =IF('Raw Data'!$B15="Mentored",'Raw Data'!$I15,"") -> 67.2 | R15: =IF(AND(P15<>"",Q15<>""),Q15-P15,"") -> 6.1 | T15: =IF('Raw Data'!$K15="Low",'Raw Data'!$J15,"") | U15: =IF('Raw Data'!$K15="Medium",'Raw Data'!$J15,"") -> 81.2 | V15: =IF('Raw Data'!$K15="High",'Raw Data'!$J15,"")
A16: Decision | D16: =IF(D14<0.05,"Reject H0: the mentored and control means differ significantly.","Fail to reject H0: no statistically significant difference in means.") -> #NAME? | M16: =IF('Raw Data'!$B16="Mentored",'Raw Data'!$J16,"") -> 74.6 | N16: =IF('Raw Data'!$B16="Control",'Raw Data'!$J16,"") | P16: =IF('Raw Data'!$B16="Mentored",'Raw Data'!$H16,"") -> 56.1 | Q16: =IF('Raw Data'!$B16="Mentored",'Raw Data'!$I16,"") -> 69.4 | R16: =IF(AND(P16<>"",Q16<>""),Q16-P16,"") -> 13.3 | T16: =IF('Raw Data'!$K16="Low",'Raw Data'!$J16,"") | U16: =IF('Raw Data'!$K16="Medium",'Raw Data'!$J16,"") -> 74.6 | V16: =IF('Raw Data'!$K16="High",'Raw Data'!$J16,"")
M17: =IF('Raw Data'!$B17="Mentored",'Raw Data'!$J17,"") | N17: =IF('Raw Data'!$B17="Control",'Raw Data'!$J17,"") -> 77.2 | P17: =IF('Raw Data'!$B17="Mentored",'Raw Data'!$H17,"") | Q17: =IF('Raw Data'!$B17="Mentored",'Raw Data'!$I17,"") | R17: =IF(AND(P17<>"",Q17<>""),Q17-P17,"") | T17: =IF('Raw Data'!$K17="Low",'Raw Data'!$J17,"") | U17: =IF('Raw Data'!$K17="Medium",'Raw Data'!$J17,"") -> 77.2 | V17: =IF('Raw Data'!$K17="High",'Raw Data'!$J17,"")
M18: =IF('Raw Data'!$B18="Mentored",'Raw Data'!$J18,"") | N18: =IF('Raw Data'!$B18="Control",'Raw Data'!$J18,"") -> 84.1 | P18: =IF('Raw Data'!$B18="Mentored",'Raw Data'!$H18,"") | Q18: =IF('Raw Data'!$B18="Mentored",'Raw Data'!$I18,"") | R18: =IF(AND(P18<>"",Q18<>""),Q18-P18,"") | T18: =IF('Raw Data'!$K18="Low",'Raw Data'!$J18,"") | U18: =IF('Raw Data'!$K18="Medium",'Raw Data'!$J18,"") -> 84.1 | V18: =IF('Raw Data'!$K18="High",'Raw Data'!$J18,"")
A19: B. Paired samples t-test: mentored students before vs after the program | M19: =IF('Raw Data'!$B19="Mentored",'Raw Data'!$J19,"") -> 73 | N19: =IF('Raw Data'!$B19="Control",'Raw Data'!$J19,"") | P19: =IF('Raw Data'!$B19="Mentored",'Raw Data'!$H19,"") -> 62.9 | Q19: =IF('Raw Data'!$B19="Mentored",'Raw Data'!$I19,"") -> 72.2 | R19: =IF(AND(P19<>"",Q19<>""),Q19-P19,"") -> 9.3 | T19: =IF('Raw Data'!$K19="Low",'Raw Data'!$J19,"") -> 73 | U19: =IF('Raw Data'!$K19="Medium",'Raw Data'!$J19,"") | V19: =IF('Raw Data'!$K19="High",'Raw Data'!$J19,"")
A20: Purpose: test whether the average within-student change from Pre_Test_Score to Post_Test_Score is different from zero in the mentored group. H0: mean difference = 0. | M20: =IF('Raw Data'!$B20="Mentored",'Raw Data'!$J20,"") | N20: =IF('Raw Data'!$B20="Control",'Raw Data'!$J20,"") -> 74.7 | P20: =IF('Raw Data'!$B20="Mentored",'Raw Data'!$H20,"") | Q20: =IF('Raw Data'!$B20="Mentored",'Raw Data'!$I20,"") | R20: =IF(AND(P20<>"",Q20<>""),Q20-P20,"") | T20: =IF('Raw Data'!$K20="Low",'Raw Data'!$J20,"") -> 74.7 | U20: =IF('Raw Data'!$K20="Medium",'Raw Data'!$J20,"") | V20: =IF('Raw Data'!$K20="High",'Raw Data'!$J20,"")
M21: =IF('Raw Data'!$B21="Mentored",'Raw Data'!$J21,"") | N21: =IF('Raw Data'!$B21="Control",'Raw Data'!$J21,"") -> 77.9 | P21: =IF('Raw Data'!$B21="Mentored",'Raw Data'!$H21,"") | Q21: =IF('Raw Data'!$B21="Mentored",'Raw Data'!$I21,"") | R21: =IF(AND(P21<>"",Q21<>""),Q21-P21,"") | T21: =IF('Raw Data'!$K21="Low",'Raw Data'!$J21,"") | U21: =IF('Raw Data'!$K21="Medium",'Raw Data'!$J21,"") -> 77.9 | V21: =IF('Raw Data'!$K21="High",'Raw Data'!$J21,"")
M22: =IF('Raw Data'!$B22="Mentored",'Raw Data'!$J22,"") | N22: =IF('Raw Data'!$B22="Control",'Raw Data'!$J22,"") -> 71.1 | P22: =IF('Raw Data'!$B22="Mentored",'Raw Data'!$H22,"") | Q22: =IF('Raw Data'!$B22="Mentored",'Raw Data'!$I22,"") | R22: =IF(AND(P22<>"",Q22<>""),Q22-P22,"") | T22: =IF('Raw Data'!$K22="Low",'Raw Data'!$J22,"") | U22: =IF('Raw Data'!$K22="Medium",'Raw Data'!$J22,"") -> 71.1 | V22: =IF('Raw Data'!$K22="High",'Raw Data'!$J22,"")
A23: Metric | B23: Value | M23: =IF('Raw Data'!$B23="Mentored",'Raw Data'!$J23,"") -> 83.3 | N23: =IF('Raw Data'!$B23="Control",'Raw Data'!$J23,"") | P23: =IF('Raw Data'!$B23="Mentored",'Raw Data'!$H23,"") -> 53.1 | Q23: =IF('Raw Data'!$B23="Mentored",'Raw Data'!$I23,"") -> 69.6 | R23: =IF(AND(P23<>"",Q23<>""),Q23-P23,"") -> 16.5 | T23: =IF('Raw Data'!$K23="Low",'Raw Data'!$J23,"") | U23: =IF('Raw Data'!$K23="Medium",'Raw Data'!$J23,"") | V23: =IF('Raw Data'!$K23="High",'Raw Data'!$J23,"") -> 83.3
A24: n (paired mentored observations) | B24: =COUNT(R2:R121) -> 60 | M24: =IF('Raw Data'!$B24="Mentored",'Raw Data'!$J24,"") -> 74.8 | N24: =IF('Raw Data'!$B24="Control",'Raw Data'!$J24,"") | P24: =IF('Raw Data'!$B24="Mentored",'Raw Data'!$H24,"") -> 59.7 | Q24: =IF('Raw Data'!$B24="Mentored",'Raw Data'!$I24,"") -> 73.5 | R24: =IF(AND(P24<>"",Q24<>""),Q24-P24,"") -> 13.8 | T24: =IF('Raw Data'!$K24="Low",'Raw Data'!$J24,"") | U24: =IF('Raw Data'!$K24="Medium",'Raw Data'!$J24,"") -> 74.8 | V24: =IF('Raw Data'!$K24="High",'Raw Data'!$J24,"")
A25: Average pre-test score | B25: =AVERAGE(P2:P121) -> 59.648333 | M25: =IF('Raw Data'!$B25="Mentored",'Raw Data'!$J25,"") | N25: =IF('Raw Data'!$B25="Control",'Raw Data'!$J25,"") -> 76.2 | P25: =IF('Raw Data'!$B25="Mentored",'Raw Data'!$H25,"") | Q25: =IF('Raw Data'!$B25="Mentored",'Raw Data'!$I25,"") | R25: =IF(AND(P25<>"",Q25<>""),Q25-P25,"") | T25: =IF('Raw Data'!$K25="Low",'Raw Data'!$J25,"") | U25: =IF('Raw Data'!$K25="Medium",'Raw Data'!$J25,"") -> 76.2 | V25: =IF('Raw Data'!$K25="High",'Raw Data'!$J25,"")
A26: Average post-test score | B26: =AVERAGE(Q2:Q121) -> 73.881667 | M26: =IF('Raw Data'!$B26="Mentored",'Raw Data'!$J26,"") -> 71.2 | N26: =IF('Raw Data'!$B26="Control",'Raw Data'!$J26,"") | P26: =IF('Raw Data'!$B26="Mentored",'Raw Data'!$H26,"") -> 59 | Q26: =IF('Raw Data'!$B26="Mentored",'Raw Data'!$I26,"") -> 72.3 | R26: =IF(AND(P26<>"",Q26<>""),Q26-P26,"") -> 13.3 | T26: =IF('Raw Data'!$K26="Low",'Raw Data'!$J26,"") | U26: =IF('Raw Data'!$K26="Medium",'Raw Data'!$J26,"") -> 71.2 | V26: =IF('Raw Data'!$K26="High",'Raw Data'!$J26,"")
A27: Mean difference (post - pre) | B27: =AVERAGE(R2:R121) -> 14.233333 | M27: =IF('Raw Data'!$B27="Mentored",'Raw Data'!$J27,"") -> 76 | N27: =IF('Raw Data'!$B27="Control",'Raw Data'!$J27,"") | P27: =IF('Raw Data'!$B27="Mentored",'Raw Data'!$H27,"") -> 57 | Q27: =IF('Raw Data'!$B27="Mentored",'Raw Data'!$I27,"") -> 72.7 | R27: =IF(AND(P27<>"",Q27<>""),Q27-P27,"") -> 15.7 | T27: =IF('Raw Data'!$K27="Low",'Raw Data'!$J27,"") | U27: =IF('Raw Data'!$K27="Medium",'Raw Data'!$J27,"") -> 76 | V27: =IF('Raw Data'!$K27="High",'Raw Data'!$J27,"")
A28: SD of paired differences | B28: =_xludf.STDEV.S(R2:R121) -> #NAME? | M28: =IF('Raw Data'!$B28="Mentored",'Raw Data'!$J28,"") | N28: =IF('Raw Data'!$B28="Control",'Raw Data'!$J28,"") -> 79.3 | P28: =IF('Raw Data'!$B28="Mentored",'Raw Data'!$H28,"") | Q28: =IF('Raw Data'!$B28="Mentored",'Raw Data'!$I28,"") | R28: =IF(AND(P28<>"",Q28<>""),Q28-P28,"") | T28: =IF('Raw Data'!$K28="Low",'Raw Data'!$J28,"") | U28: =IF('Raw Data'!$K28="Medium",'Raw Data'!$J28,"") -> 79.3 | V28: =IF('Raw Data'!$K28="High",'Raw Data'!$J28,"")
A29: t-statistic | B29: =B27/(B28/SQRT(B24)) -> #NAME? | M29: =IF('Raw Data'!$B29="Mentored",'Raw Data'!$J29,"") | N29: =IF('Raw Data'!$B29="Control",'Raw Data'!$J29,"") -> 83 | P29: =IF('Raw Data'!$B29="Mentored",'Raw Data'!$H29,"") | Q29: =IF('Raw Data'!$B29="Mentored",'Raw Data'!$I29,"") | R29: =IF(AND(P29<>"",Q29<>""),Q29-P29,"") | T29: =IF('Raw Data'!$K29="Low",'Raw Data'!$J29,"") | U29: =IF('Raw Data'!$K29="Medium",'Raw Data'!$J29,"") | V29: =IF('Raw Data'!$K29="High",'Raw Data'!$J29,"") -> 83
A30: Degrees of freedom | B30: =B24-1 -> 59 | M30: =IF('Raw Data'!$B30="Mentored",'Raw Data'!$J30,"") | N30: =IF('Raw Data'!$B30="Control",'Raw Data'!$J30,"") -> 63.2 | P30: =IF('Raw Data'!$B30="Mentored",'Raw Data'!$H30,"") | Q30: =IF('Raw Data'!$B30="Mentored",'Raw Data'!$I30,"") | R30: =IF(AND(P30<>"",Q30<>""),Q30-P30,"") | T30: =IF('Raw Data'!$K30="Low",'Raw Data'!$J30,"") | U30: =IF('Raw Data'!$K30="Medium",'Raw Data'!$J30,"") -> 63.2 | V30: =IF('Raw Data'!$K30="High",'Raw Data'!$J30,"")
A31: p-value (two-tailed) | B31: =TDIST(ABS(B29),B30,2) -> #NAME? | M31: =IF('Raw Data'!$B31="Mentored",'Raw Data'!$J31,"") | N31: =IF('Raw Data'!$B31="Control",'Raw Data'!$J31,"") -> 81.9 | P31: =IF('Raw Data'!$B31="Mentored",'Raw Data'!$H31,"") | Q31: =IF('Raw Data'!$B31="Mentored",'Raw Data'!$I31,"") | R31: =IF(AND(P31<>"",Q31<>""),Q31-P31,"") | T31: =IF('Raw Data'!$K31="Low",'Raw Data'!$J31,"") | U31: =IF('Raw Data'!$K31="Medium",'Raw Data'!$J31,"") | V31: =IF('Raw Data'!$K31="High",'Raw Data'!$J31,"") -> 81.9
A32: Decision | B32: =IF(B31<0.05,"Reject H0: mentored students improved significantly over time.","Fail to reject H0: mean improvement is not statistically significant.") -> #NAME? | M32: =IF('Raw Data'!$B32="Mentored",'Raw Data'!$J32,"") -> 83.2 | N32: =IF('Raw Data'!$B32="Control",'Raw Data'!$J32,"") | P32: =IF('Raw Data'!$B32="Mentored",'Raw Data'!$H32,"") -> 58.6 | Q32: =IF('Raw Data'!$B32="Mentored",'Raw Data'!$I32,"") -> 70.8 | R32: =IF(AND(P32<>"",Q32<>""),Q32-P32,"") -> 12.2 | T32: =IF('Raw Data'!$K32="Low",'Raw Data'!$J32,"") | U32: =IF('Raw Data'!$K32="Medium",'Raw Data'!$J32,"") | V32: =IF('Raw Data'!$K32="High",'Raw Data'!$J32,"") -> 83.2
M33: =IF('Raw Data'!$B33="Mentored",'Raw Data'!$J33,"") -> 90.9 | N33: =IF('Raw Data'!$B33="Control",'Raw Data'!$J33,"") | P33: =IF('Raw Data'!$B33="Mentored",'Raw Data'!$H33,"") -> 65.1 | Q33: =IF('Raw Data'!$B33="Mentored",'Raw Data'!$I33,"") -> 81.7 | R33: =IF(AND(P33<>"",Q33<>""),Q33-P33,"") -> 16.6 | T33: =IF('Raw Data'!$K33="Low",'Raw Data'!$J33,"") | U33: =IF('Raw Data'!$K33="Medium",'Raw Data'!$J33,"") | V33: =IF('Raw Data'!$K33="High",'Raw Data'!$J33,"") -> 90.9
A34: C. Pearson correlation and simple linear regression: study hours vs final exam score | M34: =IF('Raw Data'!$B34="Mentored",'Raw Data'!$J34,"") | N34: =IF('Raw Data'!$B34="Control",'Raw Data'!$J34,"") -> 69.6 | P34: =IF('Raw Data'!$B34="Mentored",'Raw Data'!$H34,"") | Q34: =IF('Raw Data'!$B34="Mentored",'Raw Data'!$I34,"") | R34: =IF(AND(P34<>"",Q34<>""),Q34-P34,"") | T34: =IF('Raw Data'!$K34="Low",'Raw Data'!$J34,"") -> 69.6 | U34: =IF('Raw Data'!$K34="Medium",'Raw Data'!$J34,"") | V34: =IF('Raw Data'!$K34="High",'Raw Data'!$J34,"")
A35: Purpose: quantify the strength and direction of the linear relationship between weekly study hours and final exam score, then estimate a prediction line. | M35: =IF('Raw Data'!$B35="Mentored",'Raw Data'!$J35,"") -> 81.5 | N35: =IF('Raw Data'!$B35="Control",'Raw Data'!$J35,"") | P35: =IF('Raw Data'!$B35="Mentored",'Raw Data'!$H35,"") -> 53.4 | Q35: =IF('Raw Data'!$B35="Mentored",'Raw Data'!$I35,"") -> 72.1 | R35: =IF(AND(P35<>"",Q35<>""),Q35-P35,"") -> 18.7 | T35: =IF('Raw Data'!$K35="Low",'Raw Data'!$J35,"") | U35: =IF('Raw Data'!$K35="Medium",'Raw Data'!$J35,"") | V35: =IF('Raw Data'!$K35="High",'Raw Data'!$J35,"") -> 81.5
M36: =IF('Raw Data'!$B36="Mentored",'Raw Data'!$J36,"") -> 73.1 | N36: =IF('Raw Data'!$B36="Control",'Raw Data'!$J36,"") | P36: =IF('Raw Data'!$B36="Mentored",'Raw Data'!$H36,"") -> 56.2 | Q36: =IF('Raw Data'!$B36="Mentored",'Raw Data'!$I36,"") -> 69.1 | R36: =IF(AND(P36<>"",Q36<>""),Q36-P36,"") -> 12.9 | T36: =IF('Raw Data'!$K36="Low",'Raw Data'!$J36,"") | U36: =IF('Raw Data'!$K36="Medium",'Raw Data'!$J36,"") -> 73.1 | V36: =IF('Raw Data'!$K36="High",'Raw Data'!$J36,"")
M37: =IF('Raw Data'!$B37="Mentored",'Raw Data'!$J37,"") -> 90.1 | N37: =IF('Raw Data'!$B37="Control",'Raw Data'!$J37,"") | P37: =IF('Raw Data'!$B37="Mentored",'Raw Data'!$H37,"") -> 71.7 | Q37: =IF('Raw Data'!$B37="Mentored",'Raw Data'!$I37,"") -> 88 | R37: =IF(AND(P37<>"",Q37<>""),Q37-P37,"") -> 16.3 | T37: =IF('Raw Data'!$K37="Low",'Raw Data'!$J37,"") | U37: =IF('Raw Data'!$K37="Medium",'Raw Data'!$J37,"") -> 90.1 | V37: =IF('Raw Data'!$K37="High",'Raw Data'!$J37,"")
A38: Metric | B38: Value | M38: =IF('Raw Data'!$B38="Mentored",'Raw Data'!$J38,"") | N38: =IF('Raw Data'!$B38="Control",'Raw Data'!$J38,"") -> 63.5 | P38: =IF('Raw Data'!$B38="Mentored",'Raw Data'!$H38,"") | Q38: =IF('Raw Data'!$B38="Mentored",'Raw Data'!$I38,"") | R38: =IF(AND(P38<>"",Q38<>""),Q38-P38,"") | T38: =IF('Raw Data'!$K38="Low",'Raw Data'!$J38,"") | U38: =IF('Raw Data'!$K38="Medium",'Raw Data'!$J38,"") -> 63.5 | V38: =IF('Raw Data'!$K38="High",'Raw Data'!$J38,"")
A39: Sample size | B39: =COUNT('Raw Data'!E2:E121) -> 120 | M39: =IF('Raw Data'!$B39="Mentored",'Raw Data'!$J39,"") -> 78.6 | N39: =IF('Raw Data'!$B39="Control",'Raw Data'!$J39,"") | P39: =IF('Raw Data'!$B39="Mentored",'Raw Data'!$H39,"") -> 44.2 | Q39: =IF('Raw Data'!$B39="Mentored",'Raw Data'!$I39,"") -> 63.3 | R39: =IF(AND(P39<>"",Q39<>""),Q39-P39,"") -> 19.1 | T39: =IF('Raw Data'!$K39="Low",'Raw Data'!$J39,"") | U39: =IF('Raw Data'!$K39="Medium",'Raw Data'!$J39,"") | V39: =IF('Raw Data'!$K39="High",'Raw Data'!$J39,"") -> 78.6
A40: Pearson correlation (r) | B40: =CORREL('Raw Data'!E2:E121,'Raw Data'!J2:J121) -> 0.52120611 | M40: =IF('Raw Data'!$B40="Mentored",'Raw Data'!$J40,"") -> 71 | N40: =IF('Raw Data'!$B40="Control",'Raw Data'!$J40,"") | P40: =IF('Raw Data'!$B40="Mentored",'Raw Data'!$H40,"") -> 48.8 | Q40: =IF('Raw Data'!$B40="Mentored",'Raw Data'!$I40,"") -> 64.2 | R40: =IF(AND(P40<>"",Q40<>""),Q40-P40,"") -> 15.4 | T40: =IF('Raw Data'!$K40="Low",'Raw Data'!$J40,"") -> 71 | U40: =IF('Raw Data'!$K40="Medium",'Raw Data'!$J40,"") | V40: =IF('Raw Data'!$K40="High",'Raw Data'!$J40,"")
...

Sheet Interpretation Notes
A1: How to interpret each statistical test
A4: Test | B4: When it is used | C4: Purpose in this sample | D4: What the key output means | E4: Assumptions to check | F4: How to report the result
A5: Descriptive statistics | B5: Used at the start of every analysis. | C5: Confirms whether the sample size, averages, and variability are sensible before inferential testing. | D5: Mean shows average level; SD shows spread; min and max show observed range; counts show sample composition. | E5: Check for impossible values, severe outliers, and group imbalance. | F5: Example: 'Students studied an average of X hours per week (SD = Y).'
A6: Independent samples t-test | B6: Used when comparing one numeric outcome across two unrelated groups. | C6: Used here to compare mentored vs control final exam scores. | D6: A small p-value means the observed mean difference is unlikely under the null hypothesis. Cohen’s d shows practical size of the gap. | E6: Outcome should be continuous enough; groups must be independent; severe outliers should be reviewed. | F6: Example: 'Final scores were significantly higher in the mentored group (t = X, p = Y, d = Z).'
A7: Paired samples t-test | B7: Used when the same individuals are measured twice. | C7: Used here to check whether mentored students improved from pre-test to post-test. | D7: The mean difference shows average change; a small p-value means the change is statistically significant. | E7: Differences should be roughly symmetric; the pairing must be correct for each student. | F7: Example: 'Mentored students improved significantly from pre-test to post-test (t = X, p = Y).'
A8: Pearson correlation | B8: Used when measuring the linear association between two numeric variables. | C8: Used here to assess whether study time rises together with final exam score. | D8: r ranges from -1 to +1. A positive r means both variables tend to increase together; magnitude indicates strength. | E8: Relationship should be roughly linear; strong outliers can distort the coefficient. | F8: Example: 'Study hours were positively correlated with final exam score (r = X, p = Y).'
A9: Simple linear regression | B9: Used when predicting a numeric outcome from one numeric predictor. | C9: Used here to estimate how much final exam score changes for each additional study hour. | D9: The slope is the expected score increase per extra hour; R² is the share of variance explained by the model. | E9: Linearity, constant spread of residuals, and no influential outliers should be reviewed. | F9: Example: 'Each additional study hour was associated with an expected X-point increase in final score.'
A10: One-way ANOVA | B10: Used when comparing a numeric outcome across three or more independent groups. | C10: Used here to compare final score across low, medium, and high attendance categories. | D10: A small p-value means at least one group mean differs. Eta-squared shows how much variance is explained by the grouping factor. | E10: Independent groups, approximately continuous outcome, and no major distributional problems. | F10: Example: 'Final exam score differed significantly by attendance category (F = X, p = Y).'
A13: Practical note: significance should not be read in isolation. A very small p-value can still correspond to a trivial effect, while a meaningful effect in a small sample may deserve discussion even if p is slightly above 0.05.

Sheet Dashboard
A1: Visual dashboard
A4: Overall mean final score | D4: Mentored mean final score | G4: Control mean final score | J4: Study-hours correlation (r)
A6: ='Descriptive Stats'!B11 -> 77.6125 | D6: ='Test Results'!B10 -> 79.981667 | G6: ='Test Results'!C10 -> 75.243333 | J6: ='Test Results'!B40 -> 0.52120611
A9: =IF(AND('Test Results'!D14<0.05,'Test Results'!B31<0.05,'Test Results'!B42<0.05,'Test Results'!E66<0.05),"All headline tests in this sample are statistically significant at the 5% level.","One or more headline tests are not statistically significant at the 5% level.") -> #NAME?
A21: Interpretation: the mentored group has the higher average final score, consistent with the t-test. | G21: Interpretation: the upward trend line indicates a positive study-hours relationship with performance.
A32: Interpretation: students with higher attendance tend to have higher median and average final scores. | G32: Interpretation: the mentored group improved materially from baseline to post-test.
